Workbook

Sheet Centralizator
B6: Criteriu | C6: Praguri (conform documentului Anexa2-Informatica.pdf) vezi http://informatica-universitaria.ro/ppages/16/ | D6: Realizat | E6: Criteriu îndeplinit (DA/NU)
B7: Perspectiva B | C7: asistent: 2 (oricare dintre categorii) | D7: ='B-Reviste'!J23+'B-Conferinte'!K25 | E7: =IF(D7>=2,IF('B-Reviste'!J15>=OR2*('B-Conferinte'!K15>=2),"DA","NU"),"NU")
C8: lector: 12 (oricare dintre categorii) | E8: =IF(D7>=12,"DA","NU")
C9: conferențiar: 32 (din care 16 de categ A*, A sau B) | E9: =IF(D7>=32,IF('B-Reviste'!J22+'B-Conferinte'!K24>=16,"DA","NU"),"NU")
C10: profesor: 56 (din care 24 de categ A* sau A și 40 de categ A* sau A sau B) | E10: =IF(D7>=56,IF('B-Reviste'!J22+'B-Conferinte'!K24>=40,IF('B-Reviste'!J17+'B-Reviste'!J18+'B-Conferinte'!K19+'B-Conferinte'!K20>=24,"DA","NU"),"NU"),"NU")
B11: Perspectiva C | C11: asistent: nu se impune prag | D11: ='C-Citari-centralizare'!J13 | E11: =IF(D11>=0,IF('C-Citari-centralizare'!J12>=12,"DA","NU"),"NU")
C12: lector: 10 ( oricare dintre categorii) | E12: =IF(D11>=10,IF('C-Citari-centralizare'!J12>=10,"DA","NU"),"NU")
C13: conferențiar: 48 (din care 12 de categ A*, A sau B) | E13: =IF(D11>=48,IF('C-Citari-centralizare'!J12>=12,"DA","NU"),"NU")
C14: profesor: 120 (din care 40 de categ A*, A sau B) | E14: =IF(D11>=120,IF('C-Citari-centralizare'!J12>=40,"DA","NU"),"NU") | J14: ISI WoS
B15: Perspectiva D | C15: asistent: nu se impune prag | D15: ='D-Perspectiva D'!K22 | E15: =IF(D15>=0,"DA","NU")
C16: lector: 4 | E16: =IF(D15>=4,"DA","NU")
C17: conferențiar: 36 | E17: =IF(D15>=36,"DA","NU") | J17: Scopus
C18: profesor: 60 | E18: =IF(D15>=60,"DA","NU") | J18: Google Scholar
B19: TOTAL | C19: asistent: 2 pct | D19: =SUM(D7:D18) | E19: =IF(AND(E7="DA",E11="DA",E15="DA",D19>=2),"DA","NU")
C20: lector: 26 pct | E20: =IF(AND(E8="DA",E12="DA",E16="DA",D19>=26),"DA","NU")
C21: conferențiar: 116 pct | E21: =IF(AND(E9="DA",E13="DA",E17="DA",D19>=116),"DA","NU")
C22: Profesor: 236 pct | E22: =IF(AND(E10="DA",E14="DA",E18="DA",D19>=116),"DA","NU")
B23: Publicații A*+A | C23: conferențiar/profesor: 24 (categ A* sau A); abilitare: 12 | D23: ='B-Reviste'!J17+'B-Reviste'!J18+'B-Conferinte'!K19+'B-Conferinte'!K20 | E23: =IF(D23>=24,"DA","NU")
B24: Perspectiva D — proiect director | C24: Minim un proiect de cercetare-dezvoltare-inovare ca director, prin competiție, ≥50.000 EUR (echipă ≥2+director — declarativ) | D24: ='D-Perspectiva D'!K24 | E24: =IF(D24>=1,"DA","NU")
B25: Indicele h (Hirsch) | C25: ISI WoS | D25: 0
C26: SCOPUS | D26: 0
C27: Google Scholar | D27: 0
B29: Notă: ÎN Tabelele ce calcul A* este înlocuit cu AA pentru a nu se confunda în formula de calcul | H29: Legenda
I30: necesita actualizare referinte
I31: autocalculat
I32: autocalculat dar necesita actualizare formule
I33: nu se completeaza
B35: Abilitare | C35: Praguri pentru abilitare (2026)
C36: Perspectiva B: 44 (din care 28 de categ A*+A+B și 12 de categ A* sau A) | D36: =D7 | E36: =IF(AND(D36>=44,'B-Reviste'!J22+'B-Conferinte'!K24>=28,('B-Reviste'!J17+'B-Reviste'!J18+'B-Conferinte'!K19+'B-Conferinte'!K20)>=12),"DA","NU")
C37: Perspectiva C: 84 (din care 26 de categ A*, A sau B) | D37: =D11 | E37: =IF(AND(D37>=84,'C-Citari-centralizare'!J12>=26),"DA","NU")
C38: Perspectiva D: 48 | D38: =D15 | E38: =IF(D38>=48,"DA","NU")
B39: TOTAL abilitare | C39: toate cele trei perspective îndeplinite | E39: =IF(AND(E36="DA",E37="DA",E38="DA"),"DA","NU")

Sheet B-Reviste
Q3: Legenda
R4: necesita actualizare referinte
C5: A. LUCRĂRI PUBLICATE ÎN REVISTE | R5: autocalculat
B6: Nr.crt. | C6: Titlu | D6: Autori | E6: Revista | F6: Volum, nr., pg. | G6: An | H6: Categorie forum | I6: Nr. autori | J6: Punctaj P | K6: Citări | M6: Punctaj Citari | R6: autocalculat dar necesita actualizare formule
K7: număr | L7: punctaj
B8: 1 | C8: Titlu articol | D8: Autori | E8: Nume jurnal | F8: Vol (nr), pg | G8: 2017 | H8: (niciunul) | I8: 0 | J8: =IF(H8="AA",12,IF(H8="A",8,IF(H8="B",4,IF(H8="C",2,IF(H8="D",1,0)))))/MAX(1,I8-2) | M8: =L8
B9: 2 | C9: Titlu articol | D9: Autori | E9: Nume jurnal | F9: Vol (nr), pg | G9: 2017 | H9: (niciunul) | I9: 0 | J9: =IF(H9="AA",12,IF(H9="A",8,IF(H9="B",4,IF(H9="C",2,IF(H9="D",1,0)))))/MAX(1,I9-2) | M9: =L9
B10: 3 | C10: Titlu articol | D10: Autori | E10: Nume jurnal | F10: Vol (nr), pg | G10: 2017 | H10: (niciunul) | I10: 0 | J10: =IF(H10="AA",12,IF(H10="A",8,IF(H10="B",4,IF(H10="C",2,IF(H10="D",1,0)))))/MAX(1,I10-2) | M10: =L10
B11: 4 | C11: Titlu articol | D11: Autori | E11: Nume jurnal | F11: Vol (nr), pg | G11: 2017 | H11: (niciunul) | I11: 0 | J11: =IF(H11="AA",12,IF(H11="A",8,IF(H11="B",4,IF(H11="C",2,IF(H11="D",1,0)))))/MAX(1,I11-2) | M11: =L11
B12: 5 | C12: Titlu articol | D12: Autori | E12: Nume jurnal | F12: Vol (nr), pg | G12: 2017 | H12: (niciunul) | I12: 0 | J12: =IF(H12="AA",12,IF(H12="A",8,IF(H12="B",4,IF(H12="C",2,IF(H12="D",1,0)))))/MAX(1,I12-2) | M12: =L12
B13: 6 | C13: Titlu articol | D13: Autori | E13: Nume jurnal | F13: Vol (nr), pg | G13: 2017 | H13: (niciunul) | I13: 0 | J13: =IF(H13="AA",12,IF(H13="A",8,IF(H13="B",4,IF(H13="C",2,IF(H13="D",1,0)))))/MAX(1,I13-2) | M13: =L13
B14: 7 | C14: Titlu articol | D14: Autori | E14: Nume jurnal | F14: Vol (nr), pg | G14: 2017 | H14: (niciunul) | I14: 0 | J14: =IF(H14="AA",12,IF(H14="A",8,IF(H14="B",4,IF(H14="C",2,IF(H14="D",1,0)))))/MAX(1,I14-2) | M14: =L14
B15: 8 | C15: Titlu articol | D15: Autori | E15: Nume jurnal | F15: Vol (nr), pg | G15: 2017 | H15: (niciunul) | I15: 0 | J15: =IF(H15="AA",12,IF(H15="A",8,IF(H15="B",4,IF(H15="C",2,IF(H15="D",1,0)))))/MAX(1,I15-2) | M15: =L15
C17: Total categoria A* | J17: =SUMIF(H8:H15,"=AA",J8:J15)
C18: Total categoria A | J18: =SUMIF(H8:H15,"=A",J8:J15)
C19: Total categoria B | J19: =SUMIF(H8:H15,"=B",J8:J15)
C20: Total categoria C | J20: =SUMIF(H8:H15,"=C",J8:J15)
C21: Total categoria D | J21: =SUMIF(H8:H15,"=D",J8:J15)
C22: Total categoria A*+A+B | J22: =J17+J18+J19
C23: TOTAL criteriu reviste | J23: =SUM(J17:J20) | K23: =SUM(K8:K15) | L23: =SUM(L8:L15) | M23: =SUM(M8:M15)

Sheet B-Conferinte
C5: B. LUCRĂRI PUBLICATE ÎN VOLUME (PROCEEDINGS) ALE CONFERINȚELOR
B6: Nr.crt. | C6: Titlu | D6: Autori | E6: Conferinta | F6: Volum, nr., pg. | G6: An | H6: Categorie forum | I6: Nr. autori | J6: Volum Workshop | K6: Punctaj P | L6: Citări | N6: Punctaj Citari
L7: număr | M7: punctaj
B8: 1 | C8: Titlu lucrare | D8: autori | E8: Conferinta/workshop | F8: Informatii proceedings | G8: 2017 | H8: (niciunul) | I8: 0 | J8: NU | K8: =IF(H8="AA",12, IF(H8="A",8,IF(H8="B",4,IF(H8="C",2,IF(H8="D",1,0)))))/MAX(1,I8-2)/(1+IF(J8="nu",0,1)) | N8: =M8
B9: 2 | C9: Titlu lucrare | D9: autori | E9: Conferinta/workshop | F9: Informatii proceedings | G9: 2017 | H9: (niciunul) | I9: 0 | J9: NU | K9: =IF(H9="AA",12, IF(H9="A",8,IF(H9="B",4,IF(H9="C",2,IF(H9="D",1,0)))))/MAX(1,I9-2)/(1+IF(J9="nu",0,1)) | N9: =M9
B10: 3 | C10: Titlu lucrare | D10: autori | E10: Conferinta/workshop | F10: Informatii proceedings | G10: 2017 | H10: (niciunul) | I10: 0 | J10: NU | K10: =IF(H10="AA",12, IF(H10="A",8,IF(H10="B",4,IF(H10="C",2,IF(H10="D",1,0)))))/MAX(1,I10-2)/(1+IF(J10="nu",0,1)) | N10: =M10
B11: 4 | C11: Titlu lucrare | D11: autori | E11: Conferinta/workshop | F11: Informatii proceedings | G11: 2017 | H11: (niciunul) | I11: 0 | J11: NU | K11: =IF(H11="AA",12, IF(H11="A",8,IF(H11="B",4,IF(H11="C",2,IF(H11="D",1,0)))))/MAX(1,I11-2)/(1+IF(J11="nu",0,1)) | N11: =M11
B12: 5 | C12: Titlu lucrare | D12: autori | E12: Conferinta/workshop | F12: Informatii proceedings | G12: 2017 | H12: (niciunul) | I12: 0 | J12: NU | K12: =IF(H12="AA",12, IF(H12="A",8,IF(H12="B",4,IF(H12="C",2,IF(H12="D",1,0)))))/MAX(1,I12-2)/(1+IF(J12="nu",0,1)) | N12: =M12
B13: 6 | C13: Titlu lucrare | D13: autori | E13: Conferinta/workshop | F13: Informatii proceedings | G13: 2017 | H13: (niciunul) | I13: 0 | J13: NU | K13: =IF(H13="AA",12, IF(H13="A",8,IF(H13="B",4,IF(H13="C",2,IF(H13="D",1,0)))))/MAX(1,I13-2)/(1+IF(J13="nu",0,1)) | N13: =M13
B14: 7 | C14: Titlu lucrare | D14: autori | E14: Conferinta/workshop | F14: Informatii proceedings | G14: 2017 | H14: (niciunul) | I14: 0 | J14: NU | K14: =IF(H14="AA",12, IF(H14="A",8,IF(H14="B",4,IF(H14="C",2,IF(H14="D",1,0)))))/MAX(1,I14-2)/(1+IF(J14="nu",0,1)) | N14: =M14
B15: 8 | C15: Titlu lucrare | D15: autori | E15: Conferinta/workshop | F15: Informatii proceedings | G15: 2017 | H15: (niciunul) | I15: 0 | J15: NU | K15: =IF(H15="AA",12, IF(H15="A",8,IF(H15="B",4,IF(H15="C",2,IF(H15="D",1,0)))))/MAX(1,I15-2)/(1+IF(J15="nu",0,1)) | N15: =M15
B16: 9 | C16: Titlu lucrare | D16: autori | E16: Conferinta/workshop | F16: Informatii proceedings | G16: 2017 | H16: (niciunul) | I16: 0 | J16: NU | K16: =IF(H16="AA",12, IF(H16="A",8,IF(H16="B",4,IF(H16="C",2,IF(H16="D",1,0)))))/MAX(1,I16-2)/(1+IF(J16="nu",0,1)) | N16: =M16
B17: 10 | C17: Titlu lucrare | D17: autori | E17: Conferinta/workshop | F17: Informatii proceedings | G17: 2017 | H17: (niciunul) | I17: 0 | J17: NU | K17: =IF(H17="AA",12, IF(H17="A",8,IF(H17="B",4,IF(H17="C",2,IF(H17="D",1,0)))))/MAX(1,I17-2)/(1+IF(J17="nu",0,1)) | N17: =M17
C19: Total categoria A* | K19: =SUMIF(H8:H17,"=AA",K8:K17)
C20: Total categoria A | K20: =SUMIF(H8:H17,"=A",K8:K17)
C21: Total categoria B | K21: =SUMIF(H8:H17,"=B",K8:K17)
C22: Total categoria C | K22: =SUMIF(H8:H17,"=C",K8:K17)
C23: Total categoria D | K23: =SUMIF(H8:H17,"=D",K8:K17)
C24: Total categoria A*+A+B | K24: =K19+K21+K20
C25: TOTAL criteriu conferinte | K25: =SUM(K19:K22) | L25: =SUM(L8:L17) | M25: =SUM(M8:M17) | N25: =SUM(N8:N17) | Q25: Legenda
R26: necesita actualizare referinte
R27: autocalculat
R28: autocalculat dar necesita actualizare formule

Sheet C-Citari-centralizare
C5: B1. Centralizator citări
I6: Număr citări | J6: Punctaj
B7: Total citări forumuri de categoria A* | I7: =SUM('C-Citari-TPL'!I22) | J7: =SUM('C-Citari-TPL'!J22)
B8: Total citări forumuri de categoria A | I8: =SUM('C-Citari-TPL'!I23) | J8: =SUM('C-Citari-TPL'!J23)
B9: Total citări forumuri de categoria B | I9: =SUM('C-Citari-TPL'!I24) | J9: =SUM('C-Citari-TPL'!J24)
B10: Total citări forumuri de categoria C | I10: =SUM('C-Citari-TPL'!I25) | J10: =SUM('C-Citari-TPL'!J25)
B11: Total citări forumuri de categoria D | I11: =SUM('C-Citari-TPL'!I26) | J11: =SUM('C-Citari-TPL'!J26)
B12: Total citări forumuri de categoria A*+A + B | I12: =SUM(I7:I9) | J12: =SUM(J7:J9)
B13: TOTAL | I13: =SUM(I7:I11) | J13: =SUM(J7:J11)
P21: Legenda
Q22: necesita actualizare referinte
Q23: autocalculat
Q24: autocalculat dar necesita actualizare formule

Sheet C-Citari-TPL
C5: B2. CITĂRI PENTRU LUCRAREA: Articol Revista 1 (Nume Jurnal, 2017)
B6: Nr.crt. | C6: Titlu | D6: Autori | E6: FORUM (Revista, Conferința) | F6: Volum, nr., pg. | G6: An | H6: Volum Workshop | I6: Categorie forum | J6: Punctaj P | N6: Legenda
O7: autocalculat
B8: 1 | C8: Titlu articol care citeaza | D8: Autori | E8: Revista/conferinta/carte etc. | F8: Informatii | G8: 2010 | H8: NU | I8: (niciunul) | J8: =IF(I8="AA",12,IF(I8="A",8,IF(I8="B",4,IF(I8="C",2,IF(I8="D",1,0)))))/(1+IF(H8="nu",0,1)) | O8: autocalculat dar necesita actualizare formule
B9: 2 | C9: Titlu articol care citeaza | D9: Autori | E9: Revista/conferinta/carte etc. | F9: Informatii | G9: 2010 | H9: NU | I9: (niciunul) | J9: =IF(I9="AA",12,IF(I9="A",8,IF(I9="B",4,IF(I9="C",2,IF(I9="D",1,0)))))/(1+IF(H9="nu",0,1))
B10: 3 | C10: Titlu articol care citeaza | D10: Autori | E10: Revista/conferinta/carte etc. | F10: Informatii | G10: 2009 | H10: NU | I10: (niciunul) | J10: =IF(I10="AA",12,IF(I10="A",8,IF(I10="B",4,IF(I10="C",2,IF(I10="D",1,0)))))/(1+IF(H10="nu",0,1))
B11: 4 | C11: Titlu articol care citeaza | D11: Autori | E11: Revista/conferinta/carte etc. | F11: Informatii | G11: 2010 | H11: NU | I11: (niciunul) | J11: =IF(I11="AA",12,IF(I11="A",8,IF(I11="B",4,IF(I11="C",2,IF(I11="D",1,0)))))/(1+IF(H11="nu",0,1))
B12: 5 | C12: Titlu articol care citeaza | D12: Autori | E12: Revista/conferinta/carte etc. | F12: Informatii | G12: 2013 | H12: NU | I12: (niciunul) | J12: =IF(I12="AA",12,IF(I12="A",8,IF(I12="B",4,IF(I12="C",2,IF(I12="D",1,0)))))/(1+IF(H12="nu",0,1))
B13: 6 | C13: Titlu articol care citeaza | D13: Autori | E13: Revista/conferinta/carte etc. | F13: Informatii | G13: 2010 | H13: NU | I13: (niciunul) | J13: =IF(I13="AA",12,IF(I13="A",8,IF(I13="B",4,IF(I13="C",2,IF(I13="D",1,0)))))/(1+IF(H13="nu",0,1))
B14: 7 | C14: Titlu articol care citeaza | D14: Autori | E14: Revista/conferinta/carte etc. | F14: Informatii | G14: 2013 | H14: NU | I14: (niciunul) | J14: =IF(I14="AA",12,IF(I14="A",8,IF(I14="B",4,IF(I14="C",2,IF(I14="D",1,0)))))/(1+IF(H14="nu",0,1))
B15: 8 | C15: Titlu articol care citeaza | D15: Autori | E15: Revista/conferinta/carte etc. | F15: Informatii | G15: 2010 | H15: NU | I15: (niciunul) | J15: =IF(I15="AA",12,IF(I15="A",8,IF(I15="B",4,IF(I15="C",2,IF(I15="D",1,0)))))/(1+IF(H15="nu",0,1))
B16: 9 | C16: Titlu articol care citeaza | D16: Autori | E16: Revista/conferinta/carte etc. | F16: Informatii | G16: 2015 | H16: NU | I16: (niciunul) | J16: =IF(I16="AA",12,IF(I16="A",8,IF(I16="B",4,IF(I16="C",2,IF(I16="D",1,0)))))/(1+IF(H16="nu",0,1))
B17: 10 | C17: Titlu articol care citeaza | D17: Autori | E17: Revista/conferinta/carte etc. | F17: Informatii | G17: 2011 | H17: NU | I17: (niciunul) | J17: =IF(I17="AA",12,IF(I17="A",8,IF(I17="B",4,IF(I17="C",2,IF(I17="D",1,0)))))/(1+IF(H17="nu",0,1))
B18: 11 | C18: Titlu articol care citeaza | D18: Autori | E18: Revista/conferinta/carte etc. | F18: Informatii | G18: 2013 | H18: NU | I18: (niciunul) | J18: =IF(I18="AA",12,IF(I18="A",8,IF(I18="B",4,IF(I18="C",2,IF(I18="D",1,0)))))/(1+IF(H18="nu",0,1))
B19: 11 | C19: Titlu articol care citeaza | D19: Autori | E19: Revista/conferinta/carte etc. | F19: Informatii | G19: 2014 | H19: NU | I19: (niciunul) | J19: =IF(I19="AA",12,IF(I19="A",8,IF(I19="B",4,IF(I19="C",2,IF(I19="D",1,0)))))/(1+IF(H19="nu",0,1))
E21: Numar autori lucrare | J21: 0
C22: Total categoria A* | I22: =COUNTIF(I8:I19,"=AA") | J22: =SUMIF(I8:I19,"=AA",J8:J19)/MAX(1,J21-2)
C23: Total categoria A | I23: =COUNTIF(I8:I19,"=A") | J23: =SUMIF(I8:I19,"=A",J8:J19)/MAX(1,J21-2)
C24: Total categoria B | I24: =COUNTIF(I8:I19,"=B") | J24: =SUMIF(I8:I19,"=B",J8:J19)/MAX(1,J21-2)
C25: Total categoria C | I25: =COUNTIF(I8:I19,"=C") | J25: =SUMIF(I8:I19,"=C",J8:J19)/MAX(1,J21-2)
C26: Total categoria D | I26: =COUNTIF(I8:I19,"=D") | J26: =SUMIF(I8:I19,"=D",J8:J19)/MAX(1,J21-2)
C27: Total categoria A*+A+B | I27: =SUM(I22:I24) | J27: =J22+J24+J23
C28: TOTAL | I28: =SUM(I22:I26) | J28: =SUM(J22:J26)

Sheet D-Perspectiva D
C7: C. Perspectiva D
B9: Nr.crt. | C9: Indicator | K9: Punctaj
B10: 1 | C10: Carti/Capitole | K10: ='Indicatorul I'!K11
B11: 2 | C11: Editor proceedings | K11: ='Indicatorul I'!K17
B12: 3 | C12: Curs in format electronic | K12: ='Indicatorul I'!K23
B13: 4 | C13: Director/editor revista | K13: ='Indicatorul I'!K29
B14: 5 | C14: Granturi | K14: ='Indicatorul I'!K35
B15: 6 | C15: Membru comitet stiintific | K15: ='Indicatorul I'!K41
B16: 7 | C16: Organizare evenimente | K16: ='Indicatorul I'!K47
B17: 8 | C17: Keynote/invited speaker | K17: ='Indicatorul I'!K53
B18: 9 | C18: Consolidarea de echipe | K18: ='Indicatorul I'!K59
B19: 10 | C19: Comisii doctorat | K19: ='Indicatorul I'!K65
B20: 11 | C20: Pozitii de conducere | K20: ='Indicatorul I'!K71
B21: 12 | C21: Premii | K21: ='Indicatorul I'!K77
H22: TOTAL | K22: =SUM(K10:K21)
C24: Număr proiecte ca director (prin competiție, ≥50.000 EUR)* | K24: 0
C25: * proiect cu echipă de cel puțin 2 membri plus directorul; competiția și componența echipei rămân declarative (verificare comisie) | O25: Legenda
P26: necesita actualizare referinte
P27: autocalculat
P28: autocalculat dar necesita actualizare formule

Sheet Indicatorul I
C7: C1. Justificări pentru indicatorul CARTI/CAPITOLE (perspectiva D)
B9: Nr.crt. | C9: Explicație / Referințe | H9: Categorie | K9: Punctaj
B10: 1
H11: TOTAL | K11: =SUM(K10:K10)
C13: C1. Justificări pentru indicatorul EDITOR PROCEEDINGS (perspectiva D)
B15: Nr.crt. | C15: Explicație / Referințe | H15: Categorie | K15: Punctaj
B16: 1
H17: TOTAL | K17: =SUM(K16)
C19: C1. Justificări pentru indicatorul CURS UNIVERSITAR IN FORMAT ELECTRONIC (perspectiva D)
B21: Nr.crt. | C21: Explicație / Referințe | H21: Categorie | K21: Punctaj
B22: 1
H23: TOTAL | K23: =SUM(K22:K22)
C25: C1. Justificări pentru indicatorul DIRECTOR/EDITOR REVISTA (perspectiva D)
B27: Nr.crt. | C27: Explicație / Referințe | H27: Categorie | K27: Punctaj
B28: 1
H29: TOTAL | K29: =SUM(K28:K28)
C31: C1. Justificări pentru indicatorul GRANTURI (perspectiva D)
B33: Nr.crt. | C33: Explicație / Referințe | H33: Categorie | K33: Punctaj
B34: 1
H35: TOTAL | K35: =SUM(K34:K34)
C37: C1. Justificări pentru indicatorul MEMBRU COMITET STIINTIFIC (perspectiva D)
B39: Nr.crt. | C39: Explicație / Referințe | H39: Categorie | K39: Punctaj
B40: 1
H41: TOTAL | K41: =SUM(K40)
C43: C1. Justificări pentru indicatorul ORGANIZARE EVENIMENTE (perspectiva D)
B45: Nr.crt. | C45: Explicație / Referințe | H45: Categorie | K45: Punctaj
B46: 1
H47: TOTAL | K47: =SUM(K46:K46)
C49: C1. Justificări pentru indicatorul KEYNOTE/INVITED SPEAKER (perspectiva D)
B51: Nr.crt. | C51: Explicație / Referințe | H51: Categorie | K51: Punctaj
B52: 1
H53: TOTAL | K53: =SUM(K52:K52)
C55: C1. Justificări pentru indicatorul Consolidarea de echipe (perspectiva D)
B57: Nr.crt. | C57: Explicație / Referințe | H57: Categorie | K57: Punctaj
B58: 1
H59: TOTAL | K59: =SUM(K58:K58)
C61: C1. Justificări pentru indicatorul COMISII DOCTORAT (perspectiva D)
B63: Nr.crt. | C63: Explicație / Referințe | H63: Categorie | K63: Punctaj
B64: 1
H65: TOTAL | K65: =SUM(K64:K64)
...
